Workbook

Sheet Raw_data
A1: Rank | B1: Title | C1: Year | D1: Genre | E1: Director | F1: Cast | G1: Language | H1: Plot | I1: Awards | J1: Production | K1: Flickmetrix_Score | L1: IMDb_10 | M1: IMDb_100 | N1: IMDb_Votes | O1: Metacritic | P1: Critic_Rating_RT | Q1: Critic_Reviews | R1: Audience_Rating | S1: Audience_Reviews | T1: Letterboxd | U1: Letterboxd_Votes | V1: Google_Score | W1: Streaming_On | X1: RT_URL | Y1: imdbID | Z1: Custom_Score
A2: 1 | B2: The Godfather | C2: 1972 | D2: Drama, Crime | E2: Francis Ford Coppola | F2: Marlon Brando, Al Pacino, James Caan, Robert Duvall | G2: en | H2: Spanning the years 1945 to 1955, a chronicle of the fictional Italian-American Corleone crime family. When organized crime family patriarch, Vito Corleone barely survives an attempt on his life, his youngest son, Michael steps in to take care of the would-be killers, launching a campaign of bloody revenge. | I2: Won 3 Oscars. Another 30 wins & 19 nominations. | J2: Paramount Pictures | K2: 93.0 | L2: 46062 | M2: 92.0 | N2: 2108796 | O2: 100.0 | P2: 96.0 | Q2: 104 | R2: 95.0 | S2: 1087289.0 | T2: 90 | U2: 1789555.0 | V2: 90.0 | W2: paramount, itunes, amzvid | X2: https://www.rottentomatoes.com/m/godfather | Y2: tt0068646 | Z2: 93.83
A3: 2 | B3: Seven Samurai | C3: 1954 | D3: Action, Drama | E3: Akira Kurosawa | F3: Toshir≈ç Mifune, Takashi Shimura, Yoshio Inaba, Seiji Miyaguchi | G3: ja | H3: A samurai answers a village's request for protection after he falls on hard times. The town needs protection from bandits, so the samurai gathers six others to help him teach the people how to defend themselves, and the villagers provide the soldiers with food. | I3: Nominated for 2 Oscars. Another 6 wins & 5 nominations. | J3: Columbia Pictures | K3: 93.0 | L3: 46181 | M3: 86.0 | N3: 381712 | O3: 98.0 | P3: 97.0 | Q3: 68 | R3: 94.0 | S3: 167123.0 | T3: 92 | U3: 318537.0 | V3: 93.0 | W3: hbo, itunes, amzvid, hbm | X3: https://www.rottentomatoes.com/m/seven_samurai_1956 | Y3: tt0047478 | Z3: 93.33
A4: 3 | B4: 12 Angry Men | C4: 1957 | D4: Drama | E4: Sidney Lumet | F4: Martin Balsam, John Fiedler, Lee J. Cobb, E.G. Marshall | G4: en | H4: The defense and the prosecution have rested and the jury is filing into the jury room to decide if a young Spanish-American is guilty or innocent of murdering his father. What begins as an open and shut case soon becomes a mini-drama of each of the jurors' prejudices and preconceptions about the trial, the accused, and each other. | I4: Nominated for 3 Oscars. Another 16 wins & 8 nominations. | J4: Criterion Collection | K4: 92.0 | L4: 9.0 | M4: 90.0 | N4: 917215 | O4: 97.0 | P4: 93.0 | Q4: 58 | R4: 94.0 | S4: 376697.0 | T4: 92 | U4: 917590.0 | V4: 91.0 | W4: itunes, amzvid | X4: https://www.rottentomatoes.com/m/1000013_12_angry_men | Y4: tt0050083 | Z4: 92.83
A5: 4 | B5: Schindler's List | C5: 1993 | D5: Drama, History, War | E5: Steven Spielberg | F5: Liam Neeson, Ben Kingsley, Ralph Fiennes, Caroline Goodall | G5: en | H5: The true story of how businessman Oskar Schindler saved over a thousand Jewish lives from the Nazis while they worked as slaves in his factory during World War II. | I5: Won 7 Oscars. Another 74 wins & 26 nominations. | J5: Universal Pictures | K5: 92.0 | L5: 9.0 | M5: 90.0 | N5: 1512905 | O5: 95.0 | P5: 93.0 | Q5: 82 | R5: 94.0 | S5: 601555.0 | T5: 90 | U5: 978054.0 | V5: 93.0 | W5: itunes, amzvid | X5: https://www.rottentomatoes.com/m/schindlers_list | Y5: tt0108052 | Z5: 92.5
A6: 5 | B6: The Godfather: Part II | C6: 1974 | D6: Drama, Crime | E6: Francis Ford Coppola | F6: Al Pacino, Robert Duvall, Diane Keaton, Robert De Niro | G6: en | H6: In the continuing saga of the Corleone crime family, a young Vito Corleone grows up in Sicily and in 1910s New York. In the 1950s, Michael Corleone attempts to expand the family business into Las Vegas, Hollywood and Cuba. | I6: Won 6 Oscars. Another 13 wins & 16 nominations. | J6: Paramount Pictures | K6: 92.0 | L6: 9.0 | M6: 90.0 | N6: 1420179 | O6: 90.0 | P6: 95.0 | Q6: 80 | R6: 94.0 | S6: 586600.0 | T6: 92 | U6: 934120.0 | V6: 89.0 | W6: paramount, itunes, amzvid | X6: https://www.rottentomatoes.com/m/godfather_part_ii/ | Y6: tt0071562 | Z6: 91.67
A7: 6 | B7: Rear Window | C7: 1954 | D7: Thriller, Mystery | E7: Alfred Hitchcock | F7: James Stewart, Grace Kelly, Wendell Corey, Thelma Ritter | G7: en | H7: A wheelchair-bound photographer spies on his neighbors from his apartment window and becomes convinced one of them has committed murder. | I7: Nominated for 4 Oscars. Another 7 wins & 7 nominations. | J7: Paramount Pictures | K7: 91.0 | L7: 46150 | M7: 85.0 | N7: 542959 | O7: 100.0 | P7: 95.0 | Q7: 94 | R7: 92.0 | S7: 303476.0 | T7: 88 | U7: 607614.0 | V7: 90.0 | W7: itunes, amzvid | X7: https://www.rottentomatoes.com/m/1017289-rear_window | Y7: tt0047396 | Z7: 91.67
A8: 7 | B8: Pulp Fiction | C8: 1994 | D8: Thriller, Crime | E8: Quentin Tarantino | F8: John Travolta, Samuel L. Jackson, Uma Thurman, Bruce Willis | G8: en | H8: A burger-loving hit man, his philosophical partner, a drug-addled gangster's moll and a washed-up boxer converge in this sprawling, comedic crime caper. Their adventures unfurl in three stories that ingeniously trip back and forth in time. | I8: Won 1 Oscar. Another 63 wins & 47 nominations. | J8: Miramax Films | K8: 91.0 | L8: 46273 | M8: 89.0 | N8: 2319136 | O8: 95.0 | P8: 94.0 | Q8: 132 | R8: 93.0 | S8: 1731042.0 | T8: 86 | U8: 2931535.0 | V8: 92.0 | W8: paramount, peacock, itunes, amzvid, hbm | X8: https://www.rottentomatoes.com/m/pulp_fiction/ | Y8: tt0110912 | Z8: 91.5
A9: 8 | B9: City Lights | C9: 1931 | D9: Comedy, Drama, Romance | E9: Charlie Chaplin | F9: Charlie Chaplin, Virginia Cherrill, Florence Lee, Harry Myers | G9: en | H9: A tramp falls in love with a beautiful blind flower girl. His on-and-off friendship with a wealthy man allows him to be the girl's benefactor and suitor. | I9: 3 wins. | J9: Twentieth Century Fox Home Entertainment | K9: 91.0 | L9: 46150 | M9: 85.0 | N9: 205619 | O9: 99.0 | P9: 94.0 | Q9: 52 | R9: 92.0 | S9: 66173.0 | T9: 86 | U9: 144013.0 | V9: 92.0 | W9: itunes, amzvid, hbm | X9: https://www.rottentomatoes.com/m/city_lights | Y9: tt0021749 | Z9: 91.33
A10: 9 | B10: Spirited Away | C10: 2001 | D10: Animation, Family, Fantasy | E10: Hayao Miyazaki | F10: Rumi Hiiragi, Miyu Irino, Mari Natsuki, Takashi Naito | G10: ja | H10: A young girl, Chihiro, becomes trapped in a strange new world of spirits. When her parents undergo a mysterious transformation, she must call upon the courage she never knew she had to free her family. | I10: Won 1 Oscar. Another 51 wins & 22 nominations. | J10: Walt Disney Pictures | K10: 90.0 | L10: 46181 | M10: 86.0 | N10: 901217 | O10: 96.0 | P10: 89.0 | Q10: 134 | R10: 93.0 | S10: 1052053.0 | T10: 88 | U10: 2478980.0 | V10: 95.0 | W10: itunes, amzvid, hbm | X10: https://www.rottentomatoes.com/m/spirited_away | Y10: tt0245429 | Z10: 91.17
A11: 10 | B11: Parasite | C11: 2019 | D11: Comedy, Thriller, Drama | E11: Bong Joon Ho | F11: Song Kang-ho, Lee Sun-kyun, Cho Yeo-jeong, Choi Woo-shik | G11: ko | H11: All unemployed, Ki-taek's family takes peculiar interest in the wealthy and glamorous Parks for their livelihood until they get entangled in an unexpected incident. | K11: 91.0 | L11: 46150 | M11: 85.0 | N11: 1050592 | O11: 97.0 | P11: 95.0 | Q11: 314 | R11: 88.0 | S11: 1273882.0 | T11: 90 | U11: 3771374.0 | V11: 90.0 | W11: itunes, amzvid | X11: https://www.rottentomatoes.com/m/parasite_2019 | Y11: tt6751668 | Z11: 90.83
A12: 11 | B12: Modern Times | C12: 1936 | D12: Comedy, Drama, Romance | E12: Charlie Chaplin | F12: Charlie Chaplin, Paulette Goddard, Henry Bergman, Tiny Sandford | G12: en | H12: A bumbling tramp desires to build a home with a young woman, yet is thwarted time and time again by his lack of experience and habit of being in the wrong place at the wrong time.. | I12: 3 wins & 1 nomination. | J12: United Artists | K12: 90.0 | L12: 46150 | M12: 85.0 | N12: 271086 | O12: 96.0 | P12: 95.0 | Q12: 72 | R12: 92.0 | S12: 97048.0 | T12: 86 | U12: 210247.0 | V12: 90.0 | W12: prime, itunes, amzvid, hbm | Y12: tt0027977 | Z12: 90.67
A13: 12 | B13: Goodfellas | C13: 1990 | D13: Drama, Crime | E13: Martin Scorsese | F13: Robert De Niro, Ray Liotta, Joe Pesci, Lorraine Bracco | G13: en | H13: The true story of Henry Hill, a half-Irish, half-Sicilian Brooklyn kid who is adopted by neighbourhood gangsters at an early age and climbs the ranks of a Mafia family under the guidance of Jimmy Conway. | I13: Won 1 Oscar. Another 42 wins & 24 nominations. | J13: Warner Bros. | K13: 90.0 | L13: 46211 | M13: 87.0 | N13: 1315490 | O13: 92.0 | P13: 91.0 | Q13: 95 | R13: 94.0 | S13: 766130.0 | T13: 90 | U13: 1435501.0 | V13: 89.0 | W13: prime, itunes, amzvid, hbm | X13: https://www.rottentomatoes.com/m/1032176-goodfellas/ | Y13: tt0099685 | Z13: 90.5
A14: 13 | B14: The Good, the Bad and the Ugly | C14: 1966 | D14: Western | E14: Sergio Leone | F14: Clint Eastwood, Eli Wallach, Lee Van Cleef, Aldo Giuffr√® | G14: it | H14: While the Civil War rages on between the Union and the Confederacy, three men ‚Äì a quiet loner, a ruthless hitman, and a Mexican bandit ‚Äì comb the American Southwest in search of a strongbox containing $200,000 in stolen gold. | I14: 1 win. | J14: United Artists | K14: 89.0 | L14: 46242 | M14: 88.0 | N14: 847249 | O14: 90.0 | P14: 89.0 | Q14: 58 | R14: 94.0 | S14: 328668.0 | T14: 90 | U14: 504912.0 | V14: 91.0 | W14: itunes, amzvid | X14: https://www.rottentomatoes.com/m/the_good_the_bad_and_the_ugly | Y14: tt0060196 | Z14: 90.33
A15: 14 | B15: Dr. Strangelove or: How I Learned to Stop Worrying and Love the Bomb | C15: 1964 | D15: Comedy, War | E15: Stanley Kubrick | F15: Peter Sellers, George C. Scott, Sterling Hayden, Keenan Wynn | G15: en | H15: After the insane General Jack D. Ripper initiates a nuclear strike on the Soviet Union, a war room full of politicians, generals and a Russian diplomat all frantically try to stop the nuclear strike. | I15: Nominated for 4 Oscars. Another 15 wins & 4 nominations. | J15: Sony Pictures | K15: 90.0 | L15: 46089 | M15: 83.0 | N15: 535648 | O15: 97.0 | P15: 93.0 | Q15: 87 | R15: 90.0 | S15: 298335.0 | T15: 86 | U15: 475057.0 | V15: 92.0 | W15: itunes, amzvid | X15: https://www.rottentomatoes.com/m/dr_strangelove | Y15: tt0057012 | Z15: 90.17
A16: 15 | B16: Casablanca | C16: 1942 | D16: Drama, Romance | E16: Michael Curtiz | F16: Humphrey Bogart, Ingrid Bergman, Paul Henreid, Claude Rains | G16: en | H16: In Casablanca, Morocco in December 1941, a cynical American expatriate meets a former lover, with unforeseen complications. | I16: Won 3 Oscars. Another 6 wins & 6 nominations. | J16: Warner Bros. Pictures | K16: 90.0 | L16: 46150 | M16: 85.0 | N16: 628003 | O16: 100.0 | P16: 96.0 | Q16: 96 | R16: 91.0 | S16: 429846.0 | T16: 86 | U16: 572792.0 | V16: 83.0 | W16: hbo, itunes, amzvid, hbm | X16: https://www.rottentomatoes.com/m/1003707_casablanca | Y16: tt0034583 | Z16: 90.17
A17: 16 | B17: The Battle of Algiers | C17: 1966 | D17: Drama, War, History | E17: Gillo Pontecorvo | F17: Brahim Hadjadj, Yacef Sa√¢di, Fouzia El Kader, Jean Martin | G17: it | H17: Tracing the struggle of the Algerian Front de Liberation Nationale to gain freedom from French colonial rule as seen through the eyes of Ali from his start as a petty thief to his rise to prominence in the organisation and capture by the French in 1957. The film traces the rebels' struggle and the increasingly extreme measures taken by the French government to quell the revolt. | I17: Nominated for 3 Oscars. Another 11 wins & 3 nominations. | J17: Rialto Pictures | K17: 90.0 | L17: 46030 | M17: 81.0 | N17: 70309 | O17: 96.0 | P17: 92.0 | Q17: 67 | R17: 91.0 | S17: 37316.0 | T17: 88 | U17: 82844.0 | V17: 92.0 | W17: itunes, amzvid, hbm | X17: https://www.rottentomatoes.com/m/the_battle_of_algiers | Y17: tt0058946 | Z17: 90.0
A18: 17 | B18: Singin' in the Rain | C18: 1952 | D18: Comedy, Romance | E18: Stanley Donen, Gene Kelly | F18: Gene Kelly, Donald O'Connor, Debbie Reynolds, Jean Hagen | G18: en | H18: In 1927 Hollywood, a silent film production company and cast make a difficult transition to sound. | I18: Nominated for 2 Oscars. Another 5 wins & 7 nominations. | J18: MGM | K18: 90.0 | L18: 46089 | M18: 83.0 | N18: 270897 | O18: 99.0 | P18: 95.0 | Q18: 62 | R18: 91.0 | S18: 242729.0 | T18: 86 | U18: 450117.0 | V18: 86.0 | W18: hbo, itunes, amzvid, hbm | X18: https://www.rottentomatoes.com/m/singin_in_the_rain/ | Y18: tt0045152 | Z18: 90.0
A19: 18 | B19: Some Like It Hot | C19: 1959 | D19: Comedy, Romance, Crime | E19: Billy Wilder | F19: Tony Curtis, Jack Lemmon, Marilyn Monroe, George Raft | G19: en | H19: Two musicians witness a mob hit and struggle to find a way out of the city before they are found by the gangsters. Their only opportunity is to join an all-girl band as they leave on a tour. To make their getaway they must first disguise themselves as women, then keep their identities secret and deal with the problems this brings - such as an attractive bandmate and a very determined suitor. | I19: Won 1 Oscar. Another 9 wins & 13 nominations. | J19: United Artists | K19: 89.0 | L19: 46061 | M19: 82.0 | N19: 293363 | O19: 98.0 | P19: 93.0 | Q19: 77 | R19: 90.0 | S19: 143114.0 | T19: 86 | U19: 264180.0 | V19: 90.0 | W19: prime, itunes, amzvid | X19: https://www.rottentomatoes.com/m/some_like_it_hot/ | Y19: tt0053291 | Z19: 89.83
A20: 19 | B20: Psycho | C20: 1960 | D20: Horror, Thriller, Mystery | E20: Alfred Hitchcock | F20: Anthony Perkins, Janet Leigh, Vera Miles, John Gavin | G20: en | H20: When larcenous real estate clerk Marion Crane goes on the lam with a wad of cash and hopes of starting a new life, she ends up at the notorious Bates Motel, where manager Norman Bates cares for his housebound mother. | I20: Nominated for 4 Oscars. Another 7 wins & 5 nominations. | J20: Paramount Pictures | K20: 89.0 | L20: 46150 | M20: 85.0 | N20: 748078 | O20: 97.0 | P20: 94.0 | Q20: 97 | R20: 92.0 | S20: 491167.0 | T20: 86 | U20: 991319.0 | V20: 85.0 | W20: itunes, amzvid | X20: https://www.rottentomatoes.com/m/psycho/ | Y20: tt0054215 | Z20: 89.83
A21: 20 | B21: Apocalypse Now | C21: 1979 | D21: Drama, War | E21: Francis Ford Coppola | F21: Martin Sheen, Marlon Brando, Albert Hall, Frederic Forrest | G21: en | H21: At the height of the Vietnam war, Captain Benjamin Willard is sent on a dangerous mission that, officially, "does not exist, nor will it ever exist." His goal is to locate - and eliminate - a mysterious Green Beret Colonel named Walter Kurtz, who has been leading his personal army on illegal guerrilla missions into enemy territory. | I21: Won 2 Oscars. Another 20 wins & 30 nominations. | J21: United Artists | K21: 89.0 | L21: 46120 | M21: 84.0 | N21: 737539 | O21: 94.0 | P21: 92.0 | Q21: 117 | R21: 91.0 | S21: 429279.0 | T21: 88 | U21: 714063.0 | V21: 89.0 | W21: itunes, amzvid | X21: https://www.rottentomatoes.com/m/apocalypse_now/ | Y21: tt0078788 | Z21: 89.67
A22: 21 | B22: Double Indemnity | C22: 1944 | D22: Crime, Thriller | E22: Billy Wilder | F22: Fred MacMurray, Barbara Stanwyck, Edward G. Robinson, Porter Hall | G22: en | H22: A rich woman and a calculating insurance agent plot to kill her unsuspecting husband after he signs a double indemnity policy. | I22: Nominated for 7 Oscars. Another 2 wins & 2 nominations. | J22: Paramount Pictures | K22: 89.0 | L22: 46089 | M22: 83.0 | N22: 173790 | O22: 95.0 | P22: 93.0 | Q22: 72 | R22: 91.0 | S22: 79935.0 | T22: 86 | U22: 167927.0 | V22: 89.0 | W22: prime, itunes, amzvid | X22: https://www.rottentomatoes.com/m/double_indemnity | Y22: tt0036775 | Z22: 89.5
A23: 22 | B23: Rashomon | C23: 1950 | D23: Crime, Drama, Mystery | E23: Akira Kurosawa | F23: Toshir≈ç Mifune, Machiko Ky≈ç, Takashi Shimura, Masayuki Mori | G23: ja | H23: Brimming with action while incisively examining the nature of truth, "Rashomon" is perhaps the finest film ever to investigate the philosophy of justice. Through an ingenious use of camera and flashbacks, Kurosawa reveals the complexities of human nature as four people recount different versions of the story of a man's murder and the rape of his wife. | K23: 89.0 | L23: 46061 | M23: 82.0 | N23: 188349 | O23: 98.0 | P23: 94.0 | Q23: 52 | R23: 90.0 | S23: 105423.0 | T23: 84 | U23: 219549.0 | V23: 88.0 | W23: itunes, amzvid, hbm | X23: https://www.rottentomatoes.com/m/rashomon | Y23: tt0042876 | Z23: 89.33
A24: 23 | B24: Lawrence of Arabia | C24: 1962 | D24: Adventure, History, War | E24: David Lean | F24: Peter O'Toole, Alec Guinness, Anthony Quinn, Jack Hawkins | G24: en | H24: The story of British officer T.E. Lawrence's mission to aid the Arab tribes in their revolt against the Ottoman Empire during the First World War. Lawrence becomes a flamboyant, messianic figure in the cause of Arab unity but his psychological instability threatens to undermine his achievements. | I24: Won 7 Oscars. Another 22 wins & 15 nominations. | J24: Columbia Pictures | K24: 89.0 | L24: 46089 | M24: 83.0 | N24: 327276 | O24: 100.0 | P24: 96.0 | Q24: 82 | R24: 89.0 | S24: 129761.0 | T24: 88 | U24: 238330.0 | V24: 80.0 | W24: itunes, amzvid | X24: https://www.rottentomatoes.com/m/lawrence_of_arabia | Y24: tt0056172 | Z24: 89.33
A25: 24 | B25: All About Eve | C25: 1950 | D25: Drama | E25: Joseph L. Mankiewicz | F25: Bette Davis, Anne Baxter, George Sanders, Celeste Holm | G25: en | H25: From the moment she glimpses her idol at the stage door, Eve Harrington is determined to take the reins of power away from the great actress Margo Channing. Eve maneuvers her way into Margo's Broadway role, becomes a sensation and even causes turmoil in the lives of Margo's director boyfriend, her playwright and his wife. Only the cynical drama critic sees through Eve, admiring her audacity and perfect pattern of deceit. | I25: Won 6 Oscars. Another 16 wins & 17 nominations. | J25: 20th Century Fox | K25: 89.0 | L25: 46061 | M25: 82.0 | N25: 143727 | O25: 98.0 | P25: 95.0 | Q25: 73 | R25: 90.0 | S25: 66740.0 | T25: 88 | U25: 109394.0 | V25: 83.0 | W25: itunes, amzvid | X25: https://www.rottentomatoes.com/m/1000626_all_about_eve | Y25: tt0042192 | Z25: 89.33
A26: 25 | B26: Portrait of a Lady on Fire | C26: 2019 | D26: Drama, Romance, History | E26: C√©line Sciamma | F26: No√©mie Merlant, Ad√®le Haenel, Lu√†na Bajrami, Valeria Golino | G26: fr | H26: On an isolated island in Brittany at the end of the eighteenth century, a female painter is obliged to paint a wedding portrait of a young woman. | K26: 89.0 | L26: 46030 | M26: 81.0 | N26: 117917 | O26: 95.0 | P26: 91.0 | Q26: 197 | R26: 89.0 | S26: 275015.0 | T26: 88 | U26: 819613.0 | V26: 91.0 | W26: itunes | X26: https://www.rottentomatoes.com/m/portrait_of_a_lady_on_fire | Y26: tt8613070 | Z26: 89.17
A27: 26 | B27: A Separation | C27: 2011 | D27: Drama | E27: Asghar Farhadi | F27: Leila Hatami, Payman Maadi, Sareh Bayat, Sarina Farhadi | G27: fa | H27: A married couple are faced with a difficult decision - to improve the life of their child by moving to another country or to stay in Iran and look after a deteriorating parent who has Alzheimer's disease. | I27: Won 1 Oscar. Another 84 wins & 30 nominations. | J27: Sony Pictures Classics | K27: 89.0 | L27: 46089 | M27: 83.0 | N27: 267944 | O27: 95.0 | P27: 91.0 | Q27: 117 | R27: 88.0 | S27: 62517.0 | T27: 88 | U27: 141543.0 | V27: 89.0 | W27: itunes, amzvid | X27: https://www.rottentomatoes.com/m/a_separation_2011 | Y27: tt1832382 | Z27: 89.0
A28: 27 | B28: One Battle After Another | C28: 2025 | D28: Action, Thriller, Crime | E28: Paul Thomas Anderson | F28: Leonardo DiCaprio, Sean Penn, Chase Infiniti, Benicio del Toro | G28: en | H28: Washed-up revolutionary Bob exists in a state of stoned paranoia, surviving off-grid with his spirited, self-reliant daughter, Willa. When his evil nemesis resurfaces after 16 years and she goes missing, the former radical scrambles to find her, father and daughter both battling the consequences of his past. | K28: 89.0 | L28: 46061 | M28: 82.0 | N28: 115333 | O28: 95.0 | P28: 91.0 | Q28: 211 | T28: 88 | X28: https://www.rottentomatoes.com/m/one_battle_after_another | Y28: tt30144839 | Z28: 89.0
A29: 28 | B29: The Lord of the Rings: The Return of the King | C29: 2003 | D29: Adventure, Fantasy, Action | E29: Peter Jackson | F29: Elijah Wood, Ian McKellen, Viggo Mortensen, Sean Astin | G29: en | H29: As armies mass for a final battle that will decide the fate of the world--and powerful, ancient forces of Light and Dark compete to determine the outcome--one member of the Fellowship of the Ring is revealed as the noble heir to the throne of the Kings of Men. Yet, the sole hope for triumph over evil lies with a brave hobbit, Frodo, who, accompanied by his loyal friend Sam and the hideous, wretched Gollum, ventures deep into the very dark heart of Mordor on his seemingly impossible quest to destroy the Ring of Power.‚Äã | I29: Won 11 Oscars. Another 164 wins & 87 nominations. | J29: New Line Cinema | K29: 89.0 | L29: 9.0 | M29: 90.0 | N29: 2064721 | O29: 94.0 | P29: 89.0 | Q29: 172 | R29: 85.0 | S29: 23617405.0 | T29: 90 | U29: 1492669.0 | V29: 85.0 | W29: hbo, itunes, amzvid, hbm | X29: https://www.rottentomatoes.com/m/the_lord_of_the_rings_the_return_of_the_king/ | Y29: tt0167260 | Z29: 88.83
A30: 29 | B30: Citizen Kane | C30: 1941 | D30: Mystery, Drama | E30: Orson Welles | F30: Orson Welles, Joseph Cotten, Dorothy Comingore, Ray Collins | G30: en | H30: Newspaper magnate Charles Foster Kane is taken from his mother as a boy and made the ward of a rich industrialist. As a result, every well-meaning, tyrannical or self-destructive move he makes for the rest of his life appears in some way to be a reaction to that deeply wounding event. | I30: Won 1 Oscar. Another 8 wins & 10 nominations. | J30: RKO Radio Pictures | K30: 89.0 | L30: 46089 | M30: 83.0 | N30: 478970 | O30: 100.0 | P30: 98.0 | Q30: 96 | R30: 87.0 | S30: 273099.0 | T30: 84 | U30: 499118.0 | V30: 81.0 | W30: itunes, amzvid, hbm | X30: https://www.rottentomatoes.com/m/citizen_kane/ | Y30: tt0033467 | Z30: 88.83
A31: 30 | B31: Metropolis | C31: 1927 | D31: Drama, Science Fiction | E31: Fritz Lang | F31: Gustav Fr√∂hlich, Brigitte Helm, Alfred Abel, Rudolf Klein-Rogge | G31: de | H31: In a futuristic city sharply divided between the rich and the poor, the son of the city's mastermind meets a prophet who predicts the coming of a savior to mediate their differences. | I31: 3 wins & 4 nominations. | J31: Paramount Pictures | K31: 88.0 | L31: 46089 | M31: 83.0 | N31: 193052 | O31: 98.0 | P31: 93.0 | Q31: 99 | R31: 89.0 | S31: 108894.0 | T31: 86 | U31: 200533.0 | V31: 84.0 | W31: itunes, amzvid | X31: https://www.rottentomatoes.com/m/1013775-metropolis | Y31: tt0017136 | Z31: 88.83
A32: 31 | B32: It's a Wonderful Life | C32: 1946 | D32: Drama, Family, Fantasy | E32: Frank Capra | F32: James Stewart, Donna Reed, Lionel Barrymore, Thomas Mitchell | G32: en | H32: A holiday favourite for generations... George Bailey has spent his entire life giving to the people of Bedford Falls. All that prevents rich skinflint Mr. Potter from taking over the entire town is George's modest building and loan company. But on Christmas Eve the business's $8,000 is lost and George's troubles begin. | I32: Nominated for 5 Oscars. Another 7 wins. | J32: Liberty Films | K32: 88.0 | L32: 46181 | M32: 86.0 | N32: 524890 | O32: 89.0 | P32: 90.0 | Q32: 75 | R32: 92.0 | S32: 320749.0 | T32: 88 | U32: 522501.0 | V32: 88.0 | W32: prime, itunes, amzvid | X32: https://www.rottentomatoes.com/m/1010792_its_a_wonderful_life | Y32: tt0038650 | Z32: 88.83
A33: 32 | B33: Sunset Blvd. | C33: 1950 | D33: Drama | E33: Billy Wilder | F33: William Holden, Gloria Swanson, Erich von Stroheim, Nancy Olson | G33: en | H33: A hack screenwriter writes a screenplay for a former silent film star who has faded into Hollywood obscurity. | I33: Won 3 Oscars. Another 19 wins & 14 nominations. | J33: Paramount Pictures | K33: 88.0 | L33: 46120 | M33: 84.0 | N33: 247384 | O33: 94.0 | P33: 95.0 | Q33: 89 | R33: 92.0 | S33: 123301.0 | T33: 88 | U33: 262498.0 | V33: 80.0 | W33: itunes, amzvid | X33: https://www.rottentomatoes.com/m/sunset_boulevard | Y33: tt0043014 | Z33: 88.83
A34: 33 | B34: The Lord of the Rings: The Fellowship of the Ring | C34: 2001 | D34: Adventure, Fantasy, Action | E34: Peter Jackson | F34: Elijah Wood, Ian McKellen, Viggo Mortensen, Sean Astin | G34: en | H34: Young hobbit Frodo Baggins, after inheriting a mysterious ring from his uncle Bilbo, must leave his home in order to keep it from falling into the hands of its evil creator. Along the way, a fellowship is formed to protect the ringbearer and make sure that the ring arrives at its final destination: Mt. Doom, the only place where it can be destroyed. | I34: Won 4 Oscars. Another 110 wins & 100 nominations. | J34: New Line Cinema | K34: 87.0 | L34: 46273 | M34: 89.0 | N34: 2094033 | O34: 92.0 | P34: 85.0 | Q34: 142 | R34: 92.0 | S34: 1546965.0 | T34: 88 | U34: 1929394.0 | V34: 86.0 | W34: hbo, itunes, amzvid, hbm | X34: https://www.rottentomatoes.com/m/the_lord_of_the_rings_the_fellowship_of_the_ring/ | Y34: tt0120737 | Z34: 88.67
A35: 34 | B35: North by Northwest | C35: 1959 | D35: Thriller, Adventure | E35: Alfred Hitchcock | F35: Cary Grant, Eva Marie Saint, James Mason, Jessie Royce Landis | G35: en | H35: Advertising man Roger Thornhill is mistaken for a spy, triggering a deadly cross-country chase. | I35: Nominated for 3 Oscars. Another 8 wins & 4 nominations. | J35: Turner Entertainment | K35: 88.0 | L35: 46089 | M35: 83.0 | N35: 358883 | O35: 98.0 | P35: 94.0 | Q35: 90 | R35: 90.0 | S35: 142001.0 | T35: 84 | U35: 265857.0 | V35: 83.0 | W35: itunes, amzvid, hbm | X35: https://www.rottentomatoes.com/m/north_by_northwest? | Y35: tt0053125 | Z35: 88.67
A36: 35 | B36: The Apartment | C36: 1960 | D36: Comedy, Drama, Romance | E36: Billy Wilder | F36: Jack Lemmon, Shirley MacLaine, Fred MacMurray, Ray Walston | G36: en | H36: Bud Baxter is a minor clerk in a huge New York insurance company, until he discovers a quick way to climb the corporate ladder. He lends out his apartment to the executives as a place to take their mistresses. Although he often has to deal with the aftermath of their visits, one night he's left with a major problem to solve. | I36: Won 5 Oscars. Another 19 wins & 8 nominations. | J36: United Artists | K36: 88.0 | L36: 46089 | M36: 83.0 | N36: 207527 | O36: 94.0 | P36: 90.0 | Q36: 93 | R36: 91.0 | S36: 109780.0 | T36: 88 | U36: 252510.0 | V36: 86.0 | W36: itunes, amzvid | X36: https://www.rottentomatoes.com/m/1001115-apartment | Y36: tt0053604 | Z36: 88.67
A37: 36 | B37: One Flew Over the Cuckoo's Nest | C37: 1975 | D37: Drama | E37: Milo≈° Forman | F37: Jack Nicholson, Brad Dourif, Louise Fletcher, Danny DeVito | G37: en | H37: A petty criminal fakes insanity to serve his sentence in a mental ward rather than prison. He soon finds himself as a leader to the other patients‚Äîand an enemy to the cruel, domineering nurse who runs the ward. | I37: Won 5 Oscars. Another 31 wins & 12 nominations. | J37: United Artists | K37: 88.0 | L37: 46211 | M37: 87.0 | N37: 1110492 | O37: 84.0 | P37: 89.0 | Q37: 91 | R37: 93.0 | S37: 421045.0 | T37: 88 | U37: 702258.0 | V37: 91.0 | W37: itunes | X37: https://www.rottentomatoes.com/m/one_flew_over_the_cuckoos_nest | Y37: tt0073486 | Z37: 88.67
A38: 37 | B38: Star Wars: Episode V - The Empire Strikes Back | C38: 1980 | D38: Adventure, Action, Science Fiction | E38: Irvin Kershner | F38: Mark Hamill, Harrison Ford, Carrie Fisher, Billy Dee Williams | G38: en | H38: The epic saga continues as Luke Skywalker, in hopes of defeating the evil Galactic Empire, learns the ways of the Jedi from aging master Yoda. But Darth Vader is more determined than ever to capture Luke. Meanwhile, rebel leader Princess Leia, cocky Han Solo, Chewbacca, and droids C-3PO and R2-D2 are thrown into various stages of capture, betrayal and despair. | I38: Won 1 Oscar. Another 15 wins & 17 nominations. | J38: Twentieth Century Fox | K38: 88.0 | L38: 46211 | M38: 87.0 | N38: 1431491 | O38: 82.0 | P38: 88.0 | Q38: 81 | R38: 93.0 | S38: 1214408.0 | T38: 88 | U38: 1521674.0 | V38: 94.0 | W38: disney, itunes, amzvid | X38: https://www.rottentomatoes.com/m/empire_strikes_back | Y38: tt0080684 | Z38: 88.67
A39: 38 | B39: Whiplash | C39: 2014 | D39: Drama, Music | E39: Damien Chazelle | F39: Miles Teller, J.K. Simmons, Paul Reiser, Melissa Benoist | G39: en | H39: Under the direction of a ruthless instructor, a talented young drummer begins to pursue perfection at any cost, even his humanity. | I39: Won 3 Oscars. Another 87 wins & 99 nominations. | J39: Sony Pictures Classics | K39: 88.0 | L39: 46150 | M39: 85.0 | N39: 1063607 | O39: 89.0 | P39: 87.0 | Q39: 231 | R39: 91.0 | S39: 1025887.0 | T39: 88 | U39: 2932518.0 | V39: 92.0 | W39: itunes, amzvid | X39: https://www.rottentomatoes.com/m/whiplash_2014 | Y39: tt2582802 | Z39: 88.67
A40: 39 | B40: Vertigo | C40: 1958 | D40: Mystery, Romance, Thriller | E40: Alfred Hitchcock | F40: James Stewart, Kim Novak, Barbara Bel Geddes, Tom Helmore | G40: en | H40: A retired San Francisco detective suffering from acrophobia investigates the strange activities of an old friend's wife, all the while becoming dangerously obsessed with her. | I40: Nominated for 2 Oscars. Another 8 wins & 3 nominations. | J40: Paramount Pictures | K40: 88.0 | L40: 46089 | M40: 83.0 | N40: 442662 | O40: 100.0 | P40: 92.0 | Q40: 78 | R40: 90.0 | S40: 267419.0 | T40: 84 | U40: 596103.0 | V40: 83.0 | W40: itunes, amzvid | X40: https://www.rottentomatoes.com/m/vertigo | Y40: tt0052357 | Z40: 88.67
...

Sheet Pivot_analysis
A3: Row Labels | B3: Average of IMDb_10 | C3: Count of IMDb_10 | F3: Row Labels | G3: Count of Title
A4: Action, Adventure | B4: 7.7 | C4: 1 | F4: Martin Scorsese | G4: 8
A5: Action, Adventure, Animation, Family | B5: 8 | C5: 1 | F5: Steven Spielberg | G5: 8
A6: Action, Adventure, Drama | B6: 7.8 | C6: 1 | F6: Stanley Kubrick | G6: 7
A7: Action, Adventure, Science Fiction | B7: 7.675 | C7: 4 | F7: Alfred Hitchcock | G7: 7
A8: Action, Adventure, Thriller | B8: 7.8 | C8: 1 | F8: Hayao Miyazaki | G8: 7
A9: Action, Crime | B9: 7.85 | C9: 2 | F9: Wes Anderson | G9: 6
A10: Action, Crime, Thriller | B10: 7.8 | C10: 3 | F10: Quentin Tarantino | G10: 6
A11: Action, Drama | B11: 8.4 | C11: 2 | F11: Alfonso Cuarón | G11: 5
A12: Action, Drama, History | B12: 8.2 | C12: 1 | F12: Christopher Nolan | G12: 5
A13: Action, Drama, Mystery, Thriller | B13: 8 | C13: 1 | F13: Denis Villeneuve | G13: 5
A14: Action, Drama, Thriller | B14: 7.8 | C14: 1 | F14: Grand Total | G14: 64
A15: Action, Drama, War | B15: 7.8 | C15: 1
A16: Action, Science Fiction | B16: 8.7 | C16: 1
A17: Action, Science Fiction, Adventure | B17: 8.8 | C17: 1
A18: Action, Thriller | B18: 8.2 | C18: 1
A19: Action, Thriller, Crime | B19: 8.2 | C19: 1
A20: Action, Thriller, Drama | B20: 7.8 | C20: 1
A21: Action, Thriller, Science Fiction | B21: 8.3666667 | C21: 3
A22: Adventure, Action | B22: 8.4 | C22: 1
A23: Adventure, Action, Science Fiction | B23: 8.65 | C23: 2
A24: Adventure, Action, Thriller | B24: 7.85 | C24: 2
A25: Adventure, Animation, Comedy, Family | B25: 7.9 | C25: 1
A26: Adventure, Comedy, Animation | B26: 7.8 | C26: 1
... A232: Grand Total | B232: 7.9694878 | C232: 449

Sheet  Clean_data
A1: Rank | B1: Title | C1: Year | D1: Genre | E1: Director | F1: Language | G1: Awards | H1: Production | I1: Flickmetrix_Score | J1: IMDb_10 | K1: IMDb_100 | L1: IMDb_Votes | M1: Metacritic | N1: Critic_Rating_RT | O1: Critic_Reviews | P1: Audience_Rating | Q1: Audience_Reviews | R1: Letterboxd | S1: Letterboxd_Votes | T1: Google_Score | U1: Streaming_On | V1: Custom_Score | W1: Gap_Score | X1: Decade
A2: 1 | B2: The Godfather | C2: 1972 | D2: Drama, Crime | E2: Francis Ford Coppola | F2: en | G2: Won 3 Oscars. Another 30 wins & 19 nominations. | H2: Paramount Pictures | I2: 93 | J2: 9.2 | K2: 92 | L2: 2108796 | M2: 100 | N2: 96 | O2: 104 | P2: 95 | Q2: 1087289 | R2: 90 | S2: 1789555 | T2: 90 | U2: paramount, itunes, amzvid | V2: 93.83 | W2: =Top_500_Movies_Ranked_by_Combined_Critics_and_Audience_Scores[[#This Row],[Critic_Rating_RT]]-Top_500_Movies_Ranked_by_Combined_Critics_and_Audience_Scores[[#This Row],[Audience_Rating]] -> 1 | X2: =FLOOR(Top_500_Movies_Ranked_by_Combined_Critics_and_Audience_Scores[[#This Row],[Year]],10) -> 1970
A3: 2 | B3: Seven Samurai | C3: 1954 | D3: Action, Drama | E3: Akira Kurosawa | F3: ja | G3: Nominated for 2 Oscars. Another 6 wins & 5 nominations. | H3: Columbia Pictures | I3: 93 | J3: 8.6 | K3: 86 | L3: 381712 | M3: 98 | N3: 97 | O3: 68 | P3: 94 | Q3: 167123 | R3: 92 | S3: 318537 | T3: 93 | U3: hbo, itunes, amzvid, hbm | V3: 93.33 | W3: =Top_500_Movies_Ranked_by_Combined_Critics_and_Audience_Scores[[#This Row],[Critic_Rating_RT]]-Top_500_Movies_Ranked_by_Combined_Critics_and_Audience_Scores[[#This Row],[Audience_Rating]] -> 3 | X3: =FLOOR(Top_500_Movies_Ranked_by_Combined_Critics_and_Audience_Scores[[#This Row],[Year]],10) -> 1950
A4: 3 | B4: 12 Angry Men | C4: 1957 | D4: Drama | E4: Sidney Lumet | F4: en | G4: Nominated for 3 Oscars. Another 16 wins & 8 nominations. | H4: Criterion Collection | I4: 92 | J4: 9 | K4: 90 | L4: 917215 | M4: 97 | N4: 93 | O4: 58 | P4: 94 | Q4: 376697 | R4: 92 | S4: 917590 | T4: 91 | U4: itunes, amzvid | V4: 92.83 | W4: =Top_500_Movies_Ranked_by_Combined_Critics_and_Audience_Scores[[#This Row],[Critic_Rating_RT]]-Top_500_Movies_Ranked_by_Combined_Critics_and_Audience_Scores[[#This Row],[Audience_Rating]] -> -1 | X4: =FLOOR(Top_500_Movies_Ranked_by_Combined_Critics_and_Audience_Scores[[#This Row],[Year]],10) -> 1950
A5: 4 | B5: Schindler's List | C5: 1993 | D5: Drama, History, War | E5: Steven Spielberg | F5: en | G5: Won 7 Oscars. Another 74 wins & 26 nominations. | H5: Universal Pictures | I5: 92 | J5: 9 | K5: 90 | L5: 1512905 | M5: 95 | N5: 93 | O5: 82 | P5: 94 | Q5: 601555 | R5: 90 | S5: 978054 | T5: 93 | U5: itunes, amzvid | V5: 92.5 | W5: =Top_500_Movies_Ranked_by_Combined_Critics_and_Audience_Scores[[#This Row],[Critic_Rating_RT]]-Top_500_Movies_Ranked_by_Combined_Critics_and_Audience_Scores[[#This Row],[Audience_Rating]] -> -1 | X5: =FLOOR(Top_500_Movies_Ranked_by_Combined_Critics_and_Audience_Scores[[#This Row],[Year]],10) -> 1990
A6: 5 | B6: The Godfather: Part II | C6: 1974 | D6: Drama, Crime | E6: Francis Ford Coppola | F6: en | G6: Won 6 Oscars. Another 13 wins & 16 nominations. | H6: Paramount Pictures | I6: 92 | J6: 9 | K6: 90 | L6: 1420179 | M6: 90 | N6: 95 | O6: 80 | P6: 94 | Q6: 586600 | R6: 92 | S6: 934120 | T6: 89 | U6: paramount, itunes, amzvid | V6: 91.67 | W6: =Top_500_Movies_Ranked_by_Combined_Critics_and_Audience_Scores[[#This Row],[Critic_Rating_RT]]-Top_500_Movies_Ranked_by_Combined_Critics_and_Audience_Scores[[#This Row],[Audience_Rating]] -> 1 | X6: =FLOOR(Top_500_Movies_Ranked_by_Combined_Critics_and_Audience_Scores[[#This Row],[Year]],10) -> 1970
A7: 6 | B7: Rear Window | C7: 1954 | D7: Thriller, Mystery | E7: Alfred Hitchcock | F7: en | G7: Nominated for 4 Oscars. Another 7 wins & 7 nominations. | H7: Paramount Pictures | I7: 91 | J7: 8.5 | K7: 85 | L7: 542959 | M7: 100 | N7: 95 | O7: 94 | P7: 92 | Q7: 303476 | R7: 88 | S7: 607614 | T7: 90 | U7: itunes, amzvid | V7: 91.67 | W7: =Top_500_Movies_Ranked_by_Combined_Critics_and_Audience_Scores[[#This Row],[Critic_Rating_RT]]-Top_500_Movies_Ranked_by_Combined_Critics_and_Audience_Scores[[#This Row],[Audience_Rating]] -> 3 | X7: =FLOOR(Top_500_Movies_Ranked_by_Combined_Critics_and_Audience_Scores[[#This Row],[Year]],10) -> 1950
A8: 7 | B8: Pulp Fiction | C8: 1994 | D8: Thriller, Crime | E8: Quentin Tarantino | F8: en | G8: Won 1 Oscar. Another 63 wins & 47 nominations. | H8: Miramax Films | I8: 91 | J8: 8.9 | K8: 89 | L8: 2319136 | M8: 95 | N8: 94 | O8: 132 | P8: 93 | Q8: 1731042 | R8: 86 | S8: 2931535 | T8: 92 | U8: paramount, peacock, itunes, amzvid, hbm | V8: 91.5 | W8: =Top_500_Movies_Ranked_by_Combined_Critics_and_Audience_Scores[[#This Row],[Critic_Rating_RT]]-Top_500_Movies_Ranked_by_Combined_Critics_and_Audience_Scores[[#This Row],[Audience_Rating]] -> 1 | X8: =FLOOR(Top_500_Movies_Ranked_by_Combined_Critics_and_Audience_Scores[[#This Row],[Year]],10) -> 1990
A9: 8 | B9: City Lights | C9: 1931 | D9: Comedy, Drama, Romance | E9: Charlie Chaplin | F9: en | G9: 3 wins. | H9: Twentieth Century Fox Home Entertainment | I9: 91 | J9: 8.5 | K9: 85 | L9: 205619 | M9: 99 | N9: 94 | O9: 52 | P9: 92 | Q9: 66173 | R9: 86 | S9: 144013 | T9: 92 | U9: itunes, amzvid, hbm | V9: 91.33 | W9: =Top_500_Movies_Ranked_by_Combined_Critics_and_Audience_Scores[[#This Row],[Critic_Rating_RT]]-Top_500_Movies_Ranked_by_Combined_Critics_and_Audience_Scores[[#This Row],[Audience_Rating]] -> 2 | X9: =FLOOR(Top_500_Movies_Ranked_by_Combined_Critics_and_Audience_Scores[[#This Row],[Year]],10) -> 1930
A10: 9 | B10: Spirited Away | C10: 2001 | D10: Animation, Family, Fantasy | E10: Hayao Miyazaki | F10: ja | G10: Won 1 Oscar. Another 51 wins & 22 nominations. | H10: Walt Disney Pictures | I10: 90 | J10: 8.6 | K10: 86 | L10: 901217 | M10: 96 | N10: 89 | O10: 134 | P10: 93 | Q10: 1052053 | R10: 88 | S10: 2478980 | T10: 95 | U10: itunes, amzvid, hbm | V10: 91.17 | W10: =Top_500_Movies_Ranked_by_Combined_Critics_and_Audience_Scores[[#This Row],[Critic_Rating_RT]]-Top_500_Movies_Ranked_by_Combined_Critics_and_Audience_Scores[[#This Row],[Audience_Rating]] -> -4 | X10: =FLOOR(Top_500_Movies_Ranked_by_Combined_Critics_and_Audience_Scores[[#This Row],[Year]],10) -> 2000
A11: 10 | B11: Parasite | C11: 2019 | D11: Comedy, Thriller, Drama | E11: Bong Joon Ho | F11: ko | I11: 91 | J11: 8.5 | K11: 85 | L11: 1050592 | M11: 97 | N11: 95 | O11: 314 | P11: 88 | Q11: 1273882 | R11: 90 | S11: 3771374 | T11: 90 | U11: itunes, amzvid | V11: 90.83 | W11: =Top_500_Movies_Ranked_by_Combined_Critics_and_Audience_Scores[[#This Row],[Critic_Rating_RT]]-Top_500_Movies_Ranked_by_Combined_Critics_and_Audience_Scores[[#This Row],[Audience_Rating]] -> 7 | X11: =FLOOR(Top_500_Movies_Ranked_by_Combined_Critics_and_Audience_Scores[[#This Row],[Year]],10) -> 2010
A12: 11 | B12: Modern Times | C12: 1936 | D12: Comedy, Drama, Romance | E12: Charlie Chaplin | F12: en | G12: 3 wins & 1 nomination. | H12: United Artists | I12: 90 | J12: 8.5 | K12: 85 | L12: 271086 | M12: 96 | N12: 95 | O12: 72 | P12: 92 | Q12: 97048 | R12: 86 | S12: 210247 | T12: 90 | U12: prime, itunes, amzvid, hbm | V12: 90.67 | W12: =Top_500_Movies_Ranked_by_Combined_Critics_and_Audience_Scores[[#This Row],[Critic_Rating_RT]]-Top_500_Movies_Ranked_by_Combined_Critics_and_Audience_Scores[[#This Row],[Audience_Rating]] -> 3 | X12: =FLOOR(Top_500_Movies_Ranked_by_Combined_Critics_and_Audience_Scores[[#This Row],[Year]],10) -> 1930
A13: 12 | B13: Goodfellas | C13: 1990 | D13: Drama, Crime | E13: Martin Scorsese | F13: en | G13: Won 1 Oscar. Another 42 wins & 24 nominations. | H13: Warner Bros. | I13: 90 | J13: 8.7 | K13: 87 | L13: 1315490 | M13: 92 | N13: 91 | O13: 95 | P13: 94 | Q13: 766130 | R13: 90 | S13: 1435501 | T13: 89 | U13: prime, itunes, amzvid, hbm | V13: 90.5 | W13: =Top_500_Movies_Ranked_by_Combined_Critics_and_Audience_Scores[[#This Row],[Critic_Rating_RT]]-Top_500_Movies_Ranked_by_Combined_Critics_and_Audience_Scores[[#This Row],[Audience_Rating]] -> -3 | X13: =FLOOR(Top_500_Movies_Ranked_by_Combined_Critics_and_Audience_Scores[[#This Row],[Year]],10) -> 1990
A14: 13 | B14: The Good, the Bad and the Ugly | C14: 1966 | D14: Western | E14: Sergio Leone | F14: it | G14: 1 win. | H14: United Artists | I14: 89 | J14: 8.8 | K14: 88 | L14: 847249 | M14: 90 | N14: 89 | O14: 58 | P14: 94 | Q14: 328668 | R14: 90 | S14: 504912 | T14: 91 | U14: itunes, amzvid | V14: 90.33 | W14: =Top_500_Movies_Ranked_by_Combined_Critics_and_Audience_Scores[[#This Row],[Critic_Rating_RT]]-Top_500_Movies_Ranked_by_Combined_Critics_and_Audience_Scores[[#This Row],[Audience_Rating]] -> -5 | X14: =FLOOR(Top_500_Movies_Ranked_by_Combined_Critics_and_Audience_Scores[[#This Row],[Year]],10) -> 1960
A15: 14 | B15: Dr. Strangelove or: How I Learned to Stop Worrying and Love the Bomb | C15: 1964 | D15: Comedy, War | E15: Stanley Kubrick | F15: en | G15: Nominated for 4 Oscars. Another 15 wins & 4 nominations. | H15: Sony Pictures | I15: 90 | J15: 8.3 | K15: 83 | L15: 535648 | M15: 97 | N15: 93 | O15: 87 | P15: 90 | Q15: 298335 | R15: 86 | S15: 475057 | T15: 92 | U15: itunes, amzvid | V15: 90.17 | W15: =Top_500_Movies_Ranked_by_Combined_Critics_and_Audience_Scores[[#This Row],[Critic_Rating_RT]]-Top_500_Movies_Ranked_by_Combined_Critics_and_Audience_Scores[[#This Row],[Audience_Rating]] -> 3 | X15: =FLOOR(Top_500_Movies_Ranked_by_Combined_Critics_and_Audience_Scores[[#This Row],[Year]],10) -> 1960
A16: 15 | B16: Casablanca | C16: 1942 | D16: Drama, Romance | E16: Michael Curtiz | F16: en | G16: Won 3 Oscars. Another 6 wins & 6 nominations. | H16: Warner Bros. Pictures | I16: 90 | J16: 8.5 | K16: 85 | L16: 628003 | M16: 100 | N16: 96 | O16: 96 | P16: 91 | Q16: 429846 | R16: 86 | S16: 572792 | T16: 83 | U16: hbo, itunes, amzvid, hbm | V16: 90.17 | W16: =Top_500_Movies_Ranked_by_Combined_Critics_and_Audience_Scores[[#This Row],[Critic_Rating_RT]]-Top_500_Movies_Ranked_by_Combined_Critics_and_Audience_Scores[[#This Row],[Audience_Rating]] -> 5 | X16: =FLOOR(Top_500_Movies_Ranked_by_Combined_Critics_and_Audience_Scores[[#This Row],[Year]],10) -> 1940
A17: 16 | B17: The Battle of Algiers | C17: 1966 | D17: Drama, War, History | E17: Gillo Pontecorvo | F17: it | G17: Nominated for 3 Oscars. Another 11 wins & 3 nominations. | H17: Rialto Pictures | I17: 90 | J17: 8.1 | K17: 81 | L17: 70309 | M17: 96 | N17: 92 | O17: 67 | P17: 91 | Q17: 37316 | R17: 88 | S17: 82844 | T17: 92 | U17: itunes, amzvid, hbm | V17: 90 | W17: =Top_500_Movies_Ranked_by_Combined_Critics_and_Audience_Scores[[#This Row],[Critic_Rating_RT]]-Top_500_Movies_Ranked_by_Combined_Critics_and_Audience_Scores[[#This Row],[Audience_Rating]] -> 1 | X17: =FLOOR(Top_500_Movies_Ranked_by_Combined_Critics_and_Audience_Scores[[#This Row],[Year]],10) -> 1960
A18: 17 | B18: Singin' in the Rain | C18: 1952 | D18: Comedy, Romance | E18: Stanley Donen, Gene Kelly | F18: en | G18: Nominated for 2 Oscars. Another 5 wins & 7 nominations. | H18: MGM | I18: 90 | J18: 8.3 | K18: 83 | L18: 270897 | M18: 99 | N18: 95 | O18: 62 | P18: 91 | Q18: 242729 | R18: 86 | S18: 450117 | T18: 86 | U18: hbo, itunes, amzvid, hbm | V18: 90 | W18: =Top_500_Movies_Ranked_by_Combined_Critics_and_Audience_Scores[[#This Row],[Critic_Rating_RT]]-Top_500_Movies_Ranked_by_Combined_Critics_and_Audience_Scores[[#This Row],[Audience_Rating]] -> 4 | X18: =FLOOR(Top_500_Movies_Ranked_by_Combined_Critics_and_Audience_Scores[[#This Row],[Year]],10) -> 1950
A19: 18 | B19: Some Like It Hot | C19: 1959 | D19: Comedy, Romance, Crime | E19: Billy Wilder | F19: en | G19: Won 1 Oscar. Another 9 wins & 13 nominations. | H19: United Artists | I19: 89 | J19: 8.2 | K19: 82 | L19: 293363 | M19: 98 | N19: 93 | O19: 77 | P19: 90 | Q19: 143114 | R19: 86 | S19: 264180 | T19: 90 | U19: prime, itunes, amzvid | V19: 89.83 | W19: =Top_500_Movies_Ranked_by_Combined_Critics_and_Audience_Scores[[#This Row],[Critic_Rating_RT]]-Top_500_Movies_Ranked_by_Combined_Critics_and_Audience_Scores[[#This Row],[Audience_Rating]] -> 3 | X19: =FLOOR(Top_500_Movies_Ranked_by_Combined_Critics_and_Audience_Scores[[#This Row],[Year]],10) -> 1950
A20: 19 | B20: Psycho | C20: 1960 | D20: Horror, Thriller, Mystery | E20: Alfred Hitchcock | F20: en | G20: Nominated for 4 Oscars. Another 7 wins & 5 nominations. | H20: Paramount Pictures | I20: 89 | J20: 8.5 | K20: 85 | L20: 748078 | M20: 97 | N20: 94 | O20: 97 | P20: 92 | Q20: 491167 | R20: 86 | S20: 991319 | T20: 85 | U20: itunes, amzvid | V20: 89.83 | W20: =Top_500_Movies_Ranked_by_Combined_Critics_and_Audience_Scores[[#This Row],[Critic_Rating_RT]]-Top_500_Movies_Ranked_by_Combined_Critics_and_Audience_Scores[[#This Row],[Audience_Rating]] -> 2 | X20: =FLOOR(Top_500_Movies_Ranked_by_Combined_Critics_and_Audience_Scores[[#This Row],[Year]],10) -> 1960
A21: 20 | B21: Apocalypse Now | C21: 1979 | D21: Drama, War | E21: Francis Ford Coppola | F21: en | G21: Won 2 Oscars. Another 20 wins & 30 nominations. | H21: United Artists | I21: 89 | J21: 8.4 | K21: 84 | L21: 737539 | M21: 94 | N21: 92 | O21: 117 | P21: 91 | Q21: 429279 | R21: 88 | S21: 714063 | T21: 89 | U21: itunes, amzvid | V21: 89.67 | W21: =Top_500_Movies_Ranked_by_Combined_Critics_and_Audience_Scores[[#This Row],[Critic_Rating_RT]]-Top_500_Movies_Ranked_by_Combined_Critics_and_Audience_Scores[[#This Row],[Audience_Rating]] -> 1 | X21: =FLOOR(Top_500_Movies_Ranked_by_Combined_Critics_and_Audience_Scores[[#This Row],[Year]],10) -> 1970
A22: 21 | B22: Double Indemnity | C22: 1944 | D22: Crime, Thriller | E22: Billy Wilder | F22: en | G22: Nominated for 7 Oscars. Another 2 wins & 2 nominations. | H22: Paramount Pictures | I22: 89 | J22: 8.3 | K22: 83 | L22: 173790 | M22: 95 | N22: 93 | O22: 72 | P22: 91 | Q22: 79935 | R22: 86 | S22: 167927 | T22: 89 | U22: prime, itunes, amzvid | V22: 89.5 | W22: =Top_500_Movies_Ranked_by_Combined_Critics_and_Audience_Scores[[#This Row],[Critic_Rating_RT]]-Top_500_Movies_Ranked_by_Combined_Critics_and_Audience_Scores[[#This Row],[Audience_Rating]] -> 2 | X22: =FLOOR(Top_500_Movies_Ranked_by_Combined_Critics_and_Audience_Scores[[#This Row],[Year]],10) -> 1940
A23: 22 | B23: Rashomon | C23: 1950 | D23: Crime, Drama, Mystery | E23: Akira Kurosawa | F23: ja | I23: 89 | J23: 8.2 | K23: 82 | L23: 188349 | M23: 98 | N23: 94 | O23: 52 | P23: 90 | Q23: 105423 | R23: 84 | S23: 219549 | T23: 88 | U23: itunes, amzvid, hbm | V23: 89.33 | W23: =Top_500_Movies_Ranked_by_Combined_Critics_and_Audience_Scores[[#This Row],[Critic_Rating_RT]]-Top_500_Movies_Ranked_by_Combined_Critics_and_Audience_Scores[[#This Row],[Audience_Rating]] -> 4 | X23: =FLOOR(Top_500_Movies_Ranked_by_Combined_Critics_and_Audience_Scores[[#This Row],[Year]],10) -> 1950
A24: 23 | B24: Lawrence of Arabia | C24: 1962 | D24: Adventure, History, War | E24: David Lean | F24: en | G24: Won 7 Oscars. Another 22 wins & 15 nominations. | H24: Columbia Pictures | I24: 89 | J24: 8.3 | K24: 83 | L24: 327276 | M24: 100 | N24: 96 | O24: 82 | P24: 89 | Q24: 129761 | R24: 88 | S24: 238330 | T24: 80 | U24: itunes, amzvid | V24: 89.33 | W24: =Top_500_Movies_Ranked_by_Combined_Critics_and_Audience_Scores[[#This Row],[Critic_Rating_RT]]-Top_500_Movies_Ranked_by_Combined_Critics_and_Audience_Scores[[#This Row],[Audience_Rating]] -> 7 | X24: =FLOOR(Top_500_Movies_Ranked_by_Combined_Critics_and_Audience_Scores[[#This Row],[Year]],10) -> 1960
A25: 24 | B25: All About Eve | C25: 1950 | D25: Drama | E25: Joseph L. Mankiewicz | F25: en | G25: Won 6 Oscars. Another 16 wins & 17 nominations. | H25: 20th Century Fox | I25: 89 | J25: 8.2 | K25: 82 | L25: 143727 | M25: 98 | N25: 95 | O25: 73 | P25: 90 | Q25: 66740 | R25: 88 | S25: 109394 | T25: 83 | U25: itunes, amzvid | V25: 89.33 | W25: =Top_500_Movies_Ranked_by_Combined_Critics_and_Audience_Scores[[#This Row],[Critic_Rating_RT]]-Top_500_Movies_Ranked_by_Combined_Critics_and_Audience_Scores[[#This Row],[Audience_Rating]] -> 5 | X25: =FLOOR(Top_500_Movies_Ranked_by_Combined_Critics_and_Audience_Scores[[#This Row],[Year]],10) -> 1950
A26: 25 | B26: Portrait of a Lady on Fire | C26: 2019 | D26: Drama, Romance, History | E26: Céline Sciamma | F26: fr | I26: 89 | J26: 8.1 | K26: 81 | L26: 117917 | M26: 95 | N26: 91 | O26: 197 | P26: 89 | Q26: 275015 | R26: 88 | S26: 819613 | T26: 91 | U26: itunes | V26: 89.17 | W26: =Top_500_Movies_Ranked_by_Combined_Critics_and_Audience_Scores[[#This Row],[Critic_Rating_RT]]-Top_500_Movies_Ranked_by_Combined_Critics_and_Audience_Scores[[#This Row],[Audience_Rating]] -> 2 | X26: =FLOOR(Top_500_Movies_Ranked_by_Combined_Critics_and_Audience_Scores[[#This Row],[Year]],10) -> 2010
A27: 26 | B27: A Separation | C27: 2011 | D27: Drama | E27: Asghar Farhadi | F27: fa | G27: Won 1 Oscar. Another 84 wins & 30 nominations. | H27: Sony Pictures Classics | I27: 89 | J27: 8.3 | K27: 83 | L27: 267944 | M27: 95 | N27: 91 | O27: 117 | P27: 88 | Q27: 62517 | R27: 88 | S27: 141543 | T27: 89 | U27: itunes, amzvid | V27: 89 | W27: =Top_500_Movies_Ranked_by_Combined_Critics_and_Audience_Scores[[#This Row],[Critic_Rating_RT]]-Top_500_Movies_Ranked_by_Combined_Critics_and_Audience_Scores[[#This Row],[Audience_Rating]] -> 3 | X27: =FLOOR(Top_500_Movies_Ranked_by_Combined_Critics_and_Audience_Scores[[#This Row],[Year]],10) -> 2010
A28: 27 | B28: One Battle After Another | C28: 2025 | D28: Action, Thriller, Crime | E28: Paul Thomas Anderson | F28: en | I28: 89 | J28: 8.2 | K28: 82 | L28: 115333 | M28: 95 | N28: 91 | O28: 211 | R28: 88 | V28: 89 | W28: =Top_500_Movies_Ranked_by_Combined_Critics_and_Audience_Scores[[#This Row],[Critic_Rating_RT]]-Top_500_Movies_Ranked_by_Combined_Critics_and_Audience_Scores[[#This Row],[Audience_Rating]] -> 91 | X28: =FLOOR(Top_500_Movies_Ranked_by_Combined_Critics_and_Audience_Scores[[#This Row],[Year]],10) -> 2020
A29: 28 | B29: The Lord of the Rings: The Return of the King | C29: 2003 | D29: Adventure, Fantasy, Action | E29: Peter Jackson | F29: en | G29: Won 11 Oscars. Another 164 wins & 87 nominations. | H29: New Line Cinema | I29: 89 | J29: 9 | K29: 90 | L29: 2064721 | M29: 94 | N29: 89 | O29: 172 | P29: 85 | Q29: 23617405 | R29: 90 | S29: 1492669 | T29: 85 | U29: hbo, itunes, amzvid, hbm | V29: 88.83 | W29: =Top_500_Movies_Ranked_by_Combined_Critics_and_Audience_Scores[[#This Row],[Critic_Rating_RT]]-Top_500_Movies_Ranked_by_Combined_Critics_and_Audience_Scores[[#This Row],[Audience_Rating]] -> 4 | X29: =FLOOR(Top_500_Movies_Ranked_by_Combined_Critics_and_Audience_Scores[[#This Row],[Year]],10) -> 2000
A30: 29 | B30: Citizen Kane | C30: 1941 | D30: Mystery, Drama | E30: Orson Welles | F30: en | G30: Won 1 Oscar. Another 8 wins & 10 nominations. | H30: RKO Radio Pictures | I30: 89 | J30: 8.3 | K30: 83 | L30: 478970 | M30: 100 | N30: 98 | O30: 96 | P30: 87 | Q30: 273099 | R30: 84 | S30: 499118 | T30: 81 | U30: itunes, amzvid, hbm | V30: 88.83 | W30: =Top_500_Movies_Ranked_by_Combined_Critics_and_Audience_Scores[[#This Row],[Critic_Rating_RT]]-Top_500_Movies_Ranked_by_Combined_Critics_and_Audience_Scores[[#This Row],[Audience_Rating]] -> 11 | X30: =FLOOR(Top_500_Movies_Ranked_by_Combined_Critics_and_Audience_Scores[[#This Row],[Year]],10) -> 1940
A31: 30 | B31: Metropolis | C31: 1927 | D31: Drama, Science Fiction | E31: Fritz Lang | F31: de | G31: 3 wins & 4 nominations. | H31: Paramount Pictures | I31: 88 | J31: 8.3 | K31: 83 | L31: 193052 | M31: 98 | N31: 93 | O31: 99 | P31: 89 | Q31: 108894 | R31: 86 | S31: 200533 | T31: 84 | U31: itunes, amzvid | V31: 88.83 | W31: =Top_500_Movies_Ranked_by_Combined_Critics_and_Audience_Scores[[#This Row],[Critic_Rating_RT]]-Top_500_Movies_Ranked_by_Combined_Critics_and_Audience_Scores[[#This Row],[Audience_Rating]] -> 4 | X31: =FLOOR(Top_500_Movies_Ranked_by_Combined_Critics_and_Audience_Scores[[#This Row],[Year]],10) -> 1920
A32: 31 | B32: It's a Wonderful Life | C32: 1946 | D32: Drama, Family, Fantasy | E32: Frank Capra | F32: en | G32: Nominated for 5 Oscars. Another 7 wins. | H32: Liberty Films | I32: 88 | J32: 8.6 | K32: 86 | L32: 524890 | M32: 89 | N32: 90 | O32: 75 | P32: 92 | Q32: 320749 | R32: 88 | S32: 522501 | T32: 88 | U32: prime, itunes, amzvid | V32: 88.83 | W32: =Top_500_Movies_Ranked_by_Combined_Critics_and_Audience_Scores[[#This Row],[Critic_Rating_RT]]-Top_500_Movies_Ranked_by_Combined_Critics_and_Audience_Scores[[#This Row],[Audience_Rating]] -> -2 | X32: =FLOOR(Top_500_Movies_Ranked_by_Combined_Critics_and_Audience_Scores[[#This Row],[Year]],10) -> 1940
A33: 32 | B33: Sunset Blvd. | C33: 1950 | D33: Drama | E33: Billy Wilder | F33: en | G33: Won 3 Oscars. Another 19 wins & 14 nominations. | H33: Paramount Pictures | I33: 88 | J33: 8.4 | K33: 84 | L33: 247384 | M33: 94 | N33: 95 | O33: 89 | P33: 92 | Q33: 123301 | R33: 88 | S33: 262498 | T33: 80 | U33: itunes, amzvid | V33: 88.83 | W33: =Top_500_Movies_Ranked_by_Combined_Critics_and_Audience_Scores[[#This Row],[Critic_Rating_RT]]-Top_500_Movies_Ranked_by_Combined_Critics_and_Audience_Scores[[#This Row],[Audience_Rating]] -> 3 | X33: =FLOOR(Top_500_Movies_Ranked_by_Combined_Critics_and_Audience_Scores[[#This Row],[Year]],10) -> 1950
A34: 33 | B34: The Lord of the Rings: The Fellowship of the Ring | C34: 2001 | D34: Adventure, Fantasy, Action | E34: Peter Jackson | F34: en | G34: Won 4 Oscars. Another 110 wins & 100 nominations. | H34: New Line Cinema | I34: 87 | J34: 8.9 | K34: 89 | L34: 2094033 | M34: 92 | N34: 85 | O34: 142 | P34: 92 | Q34: 1546965 | R34: 88 | S34: 1929394 | T34: 86 | U34: hbo, itunes, amzvid, hbm | V34: 88.67 | W34: =Top_500_Movies_Ranked_by_Combined_Critics_and_Audience_Scores[[#This Row],[Critic_Rating_RT]]-Top_500_Movies_Ranked_by_Combined_Critics_and_Audience_Scores[[#This Row],[Audience_Rating]] -> -7 | X34: =FLOOR(Top_500_Movies_Ranked_by_Combined_Critics_and_Audience_Scores[[#This Row],[Year]],10) -> 2000
A35: 34 | B35: North by Northwest | C35: 1959 | D35: Thriller, Adventure | E35: Alfred Hitchcock | F35: en | G35: Nominated for 3 Oscars. Another 8 wins & 4 nominations. | H35: Turner Entertainment | I35: 88 | J35: 8.3 | K35: 83 | L35: 358883 | M35: 98 | N35: 94 | O35: 90 | P35: 90 | Q35: 142001 | R35: 84 | S35: 265857 | T35: 83 | U35: itunes, amzvid, hbm | V35: 88.67 | W35: =Top_500_Movies_Ranked_by_Combined_Critics_and_Audience_Scores[[#This Row],[Critic_Rating_RT]]-Top_500_Movies_Ranked_by_Combined_Critics_and_Audience_Scores[[#This Row],[Audience_Rating]] -> 4 | X35: =FLOOR(Top_500_Movies_Ranked_by_Combined_Critics_and_Audience_Scores[[#This Row],[Year]],10) -> 1950
A36: 35 | B36: The Apartment | C36: 1960 | D36: Comedy, Drama, Romance | E36: Billy Wilder | F36: en | G36: Won 5 Oscars. Another 19 wins & 8 nominations. | H36: United Artists | I36: 88 | J36: 8.3 | K36: 83 | L36: 207527 | M36: 94 | N36: 90 | O36: 93 | P36: 91 | Q36: 109780 | R36: 88 | S36: 252510 | T36: 86 | U36: itunes, amzvid | V36: 88.67 | W36: =Top_500_Movies_Ranked_by_Combined_Critics_and_Audience_Scores[[#This Row],[Critic_Rating_RT]]-Top_500_Movies_Ranked_by_Combined_Critics_and_Audience_Scores[[#This Row],[Audience_Rating]] -> -1 | X36: =FLOOR(Top_500_Movies_Ranked_by_Combined_Critics_and_Audience_Scores[[#This Row],[Year]],10) -> 1960
A37: 36 | B37: One Flew Over the Cuckoo's Nest | C37: 1975 | D37: Drama | E37: Miloš Forman | F37: en | G37: Won 5 Oscars. Another 31 wins & 12 nominations. | H37: United Artists | I37: 88 | J37: 8.7 | K37: 87 | L37: 1110492 | M37: 84 | N37: 89 | O37: 91 | P37: 93 | Q37: 421045 | R37: 88 | S37: 702258 | T37: 91 | U37: itunes | V37: 88.67 | W37: =Top_500_Movies_Ranked_by_Combined_Critics_and_Audience_Scores[[#This Row],[Critic_Rating_RT]]-Top_500_Movies_Ranked_by_Combined_Critics_and_Audience_Scores[[#This Row],[Audience_Rating]] -> -4 | X37: =FLOOR(Top_500_Movies_Ranked_by_Combined_Critics_and_Audience_Scores[[#This Row],[Year]],10) -> 1970
A38: 37 | B38: Star Wars: Episode V - The Empire Strikes Back | C38: 1980 | D38: Adventure, Action, Science Fiction | E38: Irvin Kershner | F38: en | G38: Won 1 Oscar. Another 15 wins & 17 nominations. | H38: Twentieth Century Fox | I38: 88 | J38: 8.7 | K38: 87 | L38: 1431491 | M38: 82 | N38: 88 | O38: 81 | P38: 93 | Q38: 1214408 | R38: 88 | S38: 1521674 | T38: 94 | U38: disney, itunes, amzvid | V38: 88.67 | W38: =Top_500_Movies_Ranked_by_Combined_Critics_and_Audience_Scores[[#This Row],[Critic_Rating_RT]]-Top_500_Movies_Ranked_by_Combined_Critics_and_Audience_Scores[[#This Row],[Audience_Rating]] -> -5 | X38: =FLOOR(Top_500_Movies_Ranked_by_Combined_Critics_and_Audience_Scores[[#This Row],[Year]],10) -> 1980
A39: 38 | B39: Whiplash | C39: 2014 | D39: Drama, Music | E39: Damien Chazelle | F39: en | G39: Won 3 Oscars. Another 87 wins & 99 nominations. | H39: Sony Pictures Classics | I39: 88 | J39: 8.5 | K39: 85 | L39: 1063607 | M39: 89 | N39: 87 | O39: 231 | P39: 91 | Q39: 1025887 | R39: 88 | S39: 2932518 | T39: 92 | U39: itunes, amzvid | V39: 88.67 | W39: =Top_500_Movies_Ranked_by_Combined_Critics_and_Audience_Scores[[#This Row],[Critic_Rating_RT]]-Top_500_Movies_Ranked_by_Combined_Critics_and_Audience_Scores[[#This Row],[Audience_Rating]] -> -4 | X39: =FLOOR(Top_500_Movies_Ranked_by_Combined_Critics_and_Audience_Scores[[#This Row],[Year]],10) -> 2010
A40: 39 | B40: Vertigo | C40: 1958 | D40: Mystery, Romance, Thriller | E40: Alfred Hitchcock | F40: en | G40: Nominated for 2 Oscars. Another 8 wins & 3 nominations. | H40: Paramount Pictures | I40: 88 | J40: 8.3 | K40: 83 | L40: 442662 | M40: 100 | N40: 92 | O40: 78 | P40: 90 | Q40: 267419 | R40: 84 | S40: 596103 | T40: 83 | U40: itunes, amzvid | V40: 88.67 | W40: =Top_500_Movies_Ranked_by_Combined_Critics_and_Audience_Scores[[#This Row],[Critic_Rating_RT]]-Top_500_Movies_Ranked_by_Combined_Critics_and_Audience_Scores[[#This Row],[Audience_Rating]] -> 2 | X40: =FLOOR(Top_500_Movies_Ranked_by_Combined_Critics_and_Audience_Scores[[#This Row],[Year]],10) -> 1950
...

Sheet Analysis
A1: General Statistic
A3: General count of films | B3: =COUNTA(' Clean_data'!B:B) -> 450
A4: Average IMBD raiting | B4: =AVERAGE(' Clean_data'!J:J) -> 7.9694878
A5: Highest IMDB raiting | B5: =MAX(' Clean_data'!J:J) -> 9.2
A6: Lowest IMDB raiting | B6: =MIN(' Clean_data'!J:J) -> 7.1
A7: Average Metacritic | B7: =AVERAGE(' Clean_data'!M:M) -> 86.754587
A10: TOP genres | B10: Count | C10: Average IMDB per genre
A11: Drama | B11: =COUNTIF(' Clean_data'!D:D,"*Drama*") -> 297 | C11: =AVERAGEIF(' Clean_data'!D:D,"*Drama*",' Clean_data'!J:J) -> 7.9424242
A12: Crime | B12: =COUNTIF(' Clean_data'!D:D,"*Crime*") -> 68 | C12: =AVERAGEIF(' Clean_data'!D:D,"*Crime*",' Clean_data'!J:J) -> 8.0117647
A13: Comedy | B13: =COUNTIF(' Clean_data'!D:D,"*Comedy*") -> 88 | C13: =AVERAGEIF(' Clean_data'!D:D,"*Comedy*",' Clean_data'!J:J) -> 7.8772727
A14: Thriller | B14: =COUNTIF(' Clean_data'!D:D,"*Thriller*") -> 92 | C14: =AVERAGEIF(' Clean_data'!D:D,"*Thriller*",' Clean_data'!J:J) -> 7.9706522
A15: Action | B15: =COUNTIF(' Clean_data'!D:D,"*Action*") -> 52 | C15: =AVERAGEIF(' Clean_data'!D:D,"*Action*",' Clean_data'!J:J) -> 8.0807692
A16: Romance | B16: =COUNTIF(' Clean_data'!D:D,"*Romance*") -> 76 | C16: =AVERAGEIF(' Clean_data'!D:D,"*Romance*",' Clean_data'!J:J) -> 7.8986842
A17: Animation | B17: =COUNTIF(' Clean_data'!D:D,"*Animation*") -> 51 | C17: =AVERAGEIF(' Clean_data'!D:D,"*Animation*",' Clean_data'!J:J) -> 7.9921569
A18: War | B18: =COUNTIF(' Clean_data'!D:D,"*War*") -> 30 | C18: =AVERAGEIF(' Clean_data'!D:D,"*War*",' Clean_data'!J:J) -> 8.14
A21: Critics vs Audience
A22: Average gap critics vs audience | B22: =AVERAGE(' Clean_data'!W:W) -> 9
A23: MAX gap(critics higher) | B23: =MAX(' Clean_data'!W:W) -> 92
A24: MAX gap(audience higher) | B24: =MIN(' Clean_data'!W:W) -> -21
A27: Critics LIKE, audience - NO
A28: Film | B28: =INDEX(' Clean_data'!B:B,MATCH(MAX(' Clean_data'!W:W),' Clean_data'!W:W,0)) -> Past Lives
A29: Gap | B29: =MAX(' Clean_data'!W:W) -> 92
A31: Audience LIKES, critics - NO
A32: Film | B32: =INDEX(' Clean_data'!B:B,MATCH(MIN(' Clean_data'!W:W),' Clean_data'!W:W,0)) -> Fight Club
A33: Gap | B33: =MIN(' Clean_data'!W:W) -> -21
A35: Analysis by decade
A36: Decade | B36: Count of films | C36: Average IMDB
A37: 1920 | B37: =COUNTIF(' Clean_data'!X:X,Analysis!A37) -> 4 | C37: =ROUND(AVERAGEIF(' Clean_data'!X:X,Analysis!A37,' Clean_data'!J:J),2) -> 8.05
A38: 1930 | B38: =COUNTIF(' Clean_data'!X:X,Analysis!A38) -> 12 | C38: =ROUND(AVERAGEIF(' Clean_data'!X:X,Analysis!A38,' Clean_data'!J:J),2) -> 8.08
A39: 1940 | B39: =COUNTIF(' Clean_data'!X:X,Analysis!A39) -> 18 | C39: =ROUND(AVERAGEIF(' Clean_data'!X:X,Analysis!A39,' Clean_data'!J:J),2) -> 7.97
A40: 1950 | B40: =COUNTIF(' Clean_data'!X:X,Analysis!A40) -> 25 | C40: =ROUND(AVERAGEIF(' Clean_data'!X:X,Analysis!A40,' Clean_data'!J:J),2) -> 8.16
